Traceback (most recent call last):
  File "/workspace/.pyenv_mirror/user/current/lib/python3.8/site-packages/jupyter_cache/executors/utils.py", line 58, in single_nb_execution
    executenb(
  File "/workspace/.pyenv_mirror/user/current/lib/python3.8/site-packages/nbclient/client.py", line 1204, in execute
    return NotebookClient(nb=nb, resources=resources, km=km, **kwargs).execute()
  File "/workspace/.pyenv_mirror/user/current/lib/python3.8/site-packages/nbclient/util.py", line 84, in wrapped
    return just_run(coro(*args, **kwargs))
  File "/workspace/.pyenv_mirror/user/current/lib/python3.8/site-packages/nbclient/util.py", line 62, in just_run
    return loop.run_until_complete(coro)
  File "/home/gitpod/.pyenv/versions/3.8.16/lib/python3.8/asyncio/base_events.py", line 616, in run_until_complete
    return future.result()
  File "/workspace/.pyenv_mirror/user/current/lib/python3.8/site-packages/nbclient/client.py", line 663, in async_execute
    await self.async_execute_cell(
  File "/workspace/.pyenv_mirror/user/current/lib/python3.8/site-packages/nbclient/client.py", line 965, in async_execute_cell
    await self._check_raise_for_error(cell, cell_index, exec_reply)
  File "/workspace/.pyenv_mirror/user/current/lib/python3.8/site-packages/nbclient/client.py", line 862, in _check_raise_for_error
    raise CellExecutionError.from_cell_and_msg(cell, exec_reply_content)
nbclient.exceptions.CellExecutionError: An error occurred while executing the following cell:
------------------
import os, sys
sys.path.append(os.path.abspath('../'))
raise Exception(sys.path)
import tally
dataset = tally.DataSet(api_key=os.environ.get('tally_api_key'))
dataset.use_spss('./data/Example Data (A).sav')
------------------

[0;31m---------------------------------------------------------------------------[0m
[0;31mException[0m                                 Traceback (most recent call last)
Cell [0;32mIn[1], line 3[0m
[1;32m      1[0m [38;5;28;01mimport[39;00m [38;5;21;01mos[39;00m[38;5;241m,[39m [38;5;21;01msys[39;00m
[1;32m      2[0m sys[38;5;241m.[39mpath[38;5;241m.[39mappend(os[38;5;241m.[39mpath[38;5;241m.[39mabspath([38;5;124m'[39m[38;5;124m../[39m[38;5;124m'[39m))
[0;32m----> 3[0m [38;5;28;01mraise[39;00m [38;5;167;01mException[39;00m(sys[38;5;241m.[39mpath)
[1;32m      4[0m [38;5;28;01mimport[39;00m [38;5;21;01mtally[39;00m
[1;32m      5[0m dataset [38;5;241m=[39m tally[38;5;241m.[39mDataSet(api_key[38;5;241m=[39mos[38;5;241m.[39menviron[38;5;241m.[39mget([38;5;124m'[39m[38;5;124mtally_api_key[39m[38;5;124m'[39m))

[0;31mException[0m: ['/workspace/tally-client/docs', '/home/gitpod/.pyenv/versions/3.8.16/lib/python38.zip', '/home/gitpod/.pyenv/versions/3.8.16/lib/python3.8', '/home/gitpod/.pyenv/versions/3.8.16/lib/python3.8/lib-dynload', '', '/workspace/.pyenv_mirror/user/current/lib/python3.8/site-packages', '/home/gitpod/.pyenv/versions/3.8.16/lib/python3.8/site-packages', '/workspace/tally-client']
Exception: ['/workspace/tally-client/docs', '/home/gitpod/.pyenv/versions/3.8.16/lib/python38.zip', '/home/gitpod/.pyenv/versions/3.8.16/lib/python3.8', '/home/gitpod/.pyenv/versions/3.8.16/lib/python3.8/lib-dynload', '', '/workspace/.pyenv_mirror/user/current/lib/python3.8/site-packages', '/home/gitpod/.pyenv/versions/3.8.16/lib/python3.8/site-packages', '/workspace/tally-client']

