Traceback (most recent call last):
  File "/workspace/.pyenv_mirror/user/current/lib/python3.8/site-packages/jupyter_cache/executors/utils.py", line 58, in single_nb_execution
    executenb(
  File "/workspace/.pyenv_mirror/user/current/lib/python3.8/site-packages/nbclient/client.py", line 1204, in execute
    return NotebookClient(nb=nb, resources=resources, km=km, **kwargs).execute()
  File "/workspace/.pyenv_mirror/user/current/lib/python3.8/site-packages/nbclient/util.py", line 84, in wrapped
    return just_run(coro(*args, **kwargs))
  File "/workspace/.pyenv_mirror/user/current/lib/python3.8/site-packages/nbclient/util.py", line 62, in just_run
    return loop.run_until_complete(coro)
  File "/home/gitpod/.pyenv/versions/3.8.16/lib/python3.8/asyncio/base_events.py", line 616, in run_until_complete
    return future.result()
  File "/workspace/.pyenv_mirror/user/current/lib/python3.8/site-packages/nbclient/client.py", line 663, in async_execute
    await self.async_execute_cell(
  File "/workspace/.pyenv_mirror/user/current/lib/python3.8/site-packages/nbclient/client.py", line 965, in async_execute_cell
    await self._check_raise_for_error(cell, cell_index, exec_reply)
  File "/workspace/.pyenv_mirror/user/current/lib/python3.8/site-packages/nbclient/client.py", line 862, in _check_raise_for_error
    raise CellExecutionError.from_cell_and_msg(cell, exec_reply_content)
nbclient.exceptions.CellExecutionError: An error occurred while executing the following cell:
------------------
# we store the tally key in an environment variable, get in touch to get your own key
dataset = tally.DataSet(api_key=os.environ.get('tally_api_key'))
dataset.use_spss('data/Example Data (A).sav')

# also compatible with Confirmit, Nebu, Dimensions.
------------------

[0;31m---------------------------------------------------------------------------[0m
[0;31mFileNotFoundError[0m                         Traceback (most recent call last)
Cell [0;32mIn[2], line 3[0m
[1;32m      1[0m [38;5;66;03m# we store the tally key in an environment variable, get in touch to get your own key[39;00m
[1;32m      2[0m dataset [38;5;241m=[39m tally[38;5;241m.[39mDataSet(api_key[38;5;241m=[39mos[38;5;241m.[39menviron[38;5;241m.[39mget([38;5;124m'[39m[38;5;124mtally_api_key[39m[38;5;124m'[39m))
[0;32m----> 3[0m [43mdataset[49m[38;5;241;43m.[39;49m[43muse_spss[49m[43m([49m[38;5;124;43m'[39;49m[38;5;124;43mdata/Example Data (A).sav[39;49m[38;5;124;43m'[39;49m[43m)[49m
[1;32m      5[0m [38;5;66;03m# also compatible with Confirmit, Nebu, Dimensions.[39;00m

File [0;32m/workspace/.pyenv_mirror/user/current/lib/python3.8/site-packages/tally/dataset.py:108[0m, in [0;36mDataSet.use_spss[0;34m(self, file_path)[0m
[1;32m     98[0m [38;5;250m[39m[38;5;124;03m"""[39;00m
[1;32m     99[0m [38;5;124;03mLoad SPSS file into memory as the file to send with all requests.[39;00m
[1;32m    100[0m 
[0;32m   (...)[0m
[1;32m    104[0m [38;5;124;03m        Path to the sav file we want to use as our data.[39;00m
[1;32m    105[0m [38;5;124;03m"""[39;00m
[1;32m    106[0m [38;5;66;03m# this is okay because the path format will be the same as the OS running this[39;00m
[0;32m--> 108[0m [38;5;28;01mwith[39;00m [38;5;28;43mopen[39;49m[43m([49m[43mfile_path[49m[43m,[49m[43m [49m[43mmode[49m[38;5;241;43m=[39;49m[38;5;124;43m'[39;49m[38;5;124;43mrb[39;49m[38;5;124;43m'[39;49m[43m)[49m [38;5;28;01mas[39;00m file:
[1;32m    109[0m     fileContent [38;5;241m=[39m file[38;5;241m.[39mread()
[1;32m    111[0m payload[38;5;241m=[39m{}

[0;31mFileNotFoundError[0m: [Errno 2] No such file or directory: 'data/Example Data (A).sav'
FileNotFoundError: [Errno 2] No such file or directory: 'data/Example Data (A).sav'

