Traceback (most recent call last):
  File "/workspace/.pyenv_mirror/user/current/lib/python3.8/site-packages/jupyter_cache/executors/utils.py", line 58, in single_nb_execution
    executenb(
  File "/workspace/.pyenv_mirror/user/current/lib/python3.8/site-packages/nbclient/client.py", line 1204, in execute
    return NotebookClient(nb=nb, resources=resources, km=km, **kwargs).execute()
  File "/workspace/.pyenv_mirror/user/current/lib/python3.8/site-packages/nbclient/util.py", line 84, in wrapped
    return just_run(coro(*args, **kwargs))
  File "/workspace/.pyenv_mirror/user/current/lib/python3.8/site-packages/nbclient/util.py", line 62, in just_run
    return loop.run_until_complete(coro)
  File "/home/gitpod/.pyenv/versions/3.8.16/lib/python3.8/asyncio/base_events.py", line 616, in run_until_complete
    return future.result()
  File "/workspace/.pyenv_mirror/user/current/lib/python3.8/site-packages/nbclient/client.py", line 663, in async_execute
    await self.async_execute_cell(
  File "/workspace/.pyenv_mirror/user/current/lib/python3.8/site-packages/nbclient/client.py", line 965, in async_execute_cell
    await self._check_raise_for_error(cell, cell_index, exec_reply)
  File "/workspace/.pyenv_mirror/user/current/lib/python3.8/site-packages/nbclient/client.py", line 862, in _check_raise_for_error
    raise CellExecutionError.from_cell_and_msg(cell, exec_reply_content)
nbclient.exceptions.CellExecutionError: An error occurred while executing the following cell:
------------------
weighted = dataset.crosstab(x=['gender', 'urban_rural'], ci=['c%'], w='weight_c').rename(columns={"Total":"Weighted"})
unweighted = dataset.crosstab(x=['gender', 'urban_rural'], ci=['c%']).rename(columns={"Total":"Unweighted"})
pd.concat([unweighted, weighted], axis=1)
------------------

[0;31m---------------------------------------------------------------------------[0m
[0;31mNameError[0m                                 Traceback (most recent call last)
Cell [0;32mIn[5], line 3[0m
[1;32m      1[0m weighted [38;5;241m=[39m dataset[38;5;241m.[39mcrosstab(x[38;5;241m=[39m[[38;5;124m'[39m[38;5;124mgender[39m[38;5;124m'[39m, [38;5;124m'[39m[38;5;124murban_rural[39m[38;5;124m'[39m], ci[38;5;241m=[39m[[38;5;124m'[39m[38;5;124mc[39m[38;5;124m%[39m[38;5;124m'[39m], w[38;5;241m=[39m[38;5;124m'[39m[38;5;124mweight_c[39m[38;5;124m'[39m)[38;5;241m.[39mrename(columns[38;5;241m=[39m{[38;5;124m"[39m[38;5;124mTotal[39m[38;5;124m"[39m:[38;5;124m"[39m[38;5;124mWeighted[39m[38;5;124m"[39m})
[1;32m      2[0m unweighted [38;5;241m=[39m dataset[38;5;241m.[39mcrosstab(x[38;5;241m=[39m[[38;5;124m'[39m[38;5;124mgender[39m[38;5;124m'[39m, [38;5;124m'[39m[38;5;124murban_rural[39m[38;5;124m'[39m], ci[38;5;241m=[39m[[38;5;124m'[39m[38;5;124mc[39m[38;5;124m%[39m[38;5;124m'[39m])[38;5;241m.[39mrename(columns[38;5;241m=[39m{[38;5;124m"[39m[38;5;124mTotal[39m[38;5;124m"[39m:[38;5;124m"[39m[38;5;124mUnweighted[39m[38;5;124m"[39m})
[0;32m----> 3[0m [43mpd[49m[38;5;241m.[39mconcat([unweighted, weighted], axis[38;5;241m=[39m[38;5;241m1[39m)

[0;31mNameError[0m: name 'pd' is not defined
NameError: name 'pd' is not defined

